Traceback (most recent call last):
  File "/Users/runner/hostedtoolcache/Python/3.8.8/x64/lib/python3.8/site-packages/jupyter_cache/executors/utils.py", line 51, in single_nb_execution
    executenb(
  File "/Users/runner/hostedtoolcache/Python/3.8.8/x64/lib/python3.8/site-packages/nbclient/client.py", line 1112, in execute
    return NotebookClient(nb=nb, resources=resources, km=km, **kwargs).execute()
  File "/Users/runner/hostedtoolcache/Python/3.8.8/x64/lib/python3.8/site-packages/nbclient/util.py", line 74, in wrapped
    return just_run(coro(*args, **kwargs))
  File "/Users/runner/hostedtoolcache/Python/3.8.8/x64/lib/python3.8/site-packages/nbclient/util.py", line 53, in just_run
    return loop.run_until_complete(coro)
  File "/Users/runner/hostedtoolcache/Python/3.8.8/x64/lib/python3.8/asyncio/base_events.py", line 616, in run_until_complete
    return future.result()
  File "/Users/runner/hostedtoolcache/Python/3.8.8/x64/lib/python3.8/site-packages/nbclient/client.py", line 553, in async_execute
    await self.async_execute_cell(
  File "/Users/runner/hostedtoolcache/Python/3.8.8/x64/lib/python3.8/site-packages/nbclient/client.py", line 857, in async_execute_cell
    self._check_raise_for_error(cell, exec_reply)
  File "/Users/runner/hostedtoolcache/Python/3.8.8/x64/lib/python3.8/site-packages/nbclient/client.py", line 760, in _check_raise_for_error
    raise CellExecutionError.from_cell_and_msg(cell, exec_reply_content)
nbclient.exceptions.CellExecutionError: An error occurred while executing the following cell:
------------------
from statsmodels.graphics.tsaplots import plot_acf, plot_pacf
import matplotlib.pyplot as plt
import matplotlib as mpl

mpl.rc("figure", figsize=(10, 6))
plot_acf(df["Sales"], lags = 12)
------------------

[0;31m---------------------------------------------------------------------------[0m
[0;31mModuleNotFoundError[0m                       Traceback (most recent call last)
[0;32m<ipython-input-6-1b572995f3db>[0m in [0;36m<module>[0;34m[0m
[0;32m----> 1[0;31m [0;32mfrom[0m [0mstatsmodels[0m[0;34m.[0m[0mgraphics[0m[0;34m.[0m[0mtsaplots[0m [0;32mimport[0m [0mplot_acf[0m[0;34m,[0m [0mplot_pacf[0m[0;34m[0m[0;34m[0m[0m
[0m[1;32m      2[0m [0;32mimport[0m [0mmatplotlib[0m[0;34m.[0m[0mpyplot[0m [0;32mas[0m [0mplt[0m[0;34m[0m[0;34m[0m[0m
[1;32m      3[0m [0;32mimport[0m [0mmatplotlib[0m [0;32mas[0m [0mmpl[0m[0;34m[0m[0;34m[0m[0m
[1;32m      4[0m [0;34m[0m[0m
[1;32m      5[0m [0mmpl[0m[0;34m.[0m[0mrc[0m[0;34m([0m[0;34m"figure"[0m[0;34m,[0m [0mfigsize[0m[0;34m=[0m[0;34m([0m[0;36m10[0m[0;34m,[0m [0;36m6[0m[0;34m)[0m[0;34m)[0m[0;34m[0m[0;34m[0m[0m

[0;31mModuleNotFoundError[0m: No module named 'statsmodels'
ModuleNotFoundError: No module named 'statsmodels'

